Workbook

Sheet Financial Data
A1: Company Name: | B1: DXone ERP
A2: Financial Year Start: | B2: January
A5: Classification | B5: Account Name | C5: 45627 | D5: Jan 2025 | E5: Feb 2025 | F5: Mar 2025 | G5: Apr 2025 | H5: May 2025
B6: Revenue
A7: REV | B7: DXOne ERP - Licence Tier 3 | C7: 63393.16 | D7: =Sheet1!C5 -> 5813.85 | E7: =Sheet1!D5 -> 5813.85 | F7: =Sheet1!E5 -> 5873.85 | G7: =Sheet1!F5 -> 5873.85 | H7: =Sheet1!G5 -> 5248.18
A8: REV | B8: Other Optional Suites | D8: =VLOOKUP($B8,Sheet1!$B$2:$G$52,MATCH('Financial Data'!D$5,Sheet1!$B$2:$G$2,0),0) -> 0 | E8: =VLOOKUP($B8,Sheet1!$B$2:$G$52,MATCH('Financial Data'!E$5,Sheet1!$B$2:$G$2,0),0) -> 0 | F8: =VLOOKUP($B8,Sheet1!$B$2:$G$52,MATCH('Financial Data'!F$5,Sheet1!$B$2:$G$2,0),0) -> 0 | G8: =VLOOKUP($B8,Sheet1!$B$2:$G$52,MATCH('Financial Data'!G$5,Sheet1!$B$2:$G$2,0),0) -> 0 | H8: =VLOOKUP($B8,Sheet1!$B$2:$G$52,MATCH('Financial Data'!H$5,Sheet1!$B$2:$G$2,0),0) -> 0
A9: REV | B9: DCA Monitoring | C9: 9788.82 | D9: =VLOOKUP($B9,Sheet1!$B$2:$G$52,MATCH('Financial Data'!D$5,Sheet1!$B$2:$G$2,0),0) -> 0 | E9: =VLOOKUP($B9,Sheet1!$B$2:$G$52,MATCH('Financial Data'!E$5,Sheet1!$B$2:$G$2,0),0) -> 0 | F9: =VLOOKUP($B9,Sheet1!$B$2:$G$52,MATCH('Financial Data'!F$5,Sheet1!$B$2:$G$2,0),0) -> 0 | G9: =VLOOKUP($B9,Sheet1!$B$2:$G$52,MATCH('Financial Data'!G$5,Sheet1!$B$2:$G$2,0),0) -> 0 | H9: =VLOOKUP($B9,Sheet1!$B$2:$G$52,MATCH('Financial Data'!H$5,Sheet1!$B$2:$G$2,0),0) -> 0
A10: REV | B10: Implementation | C10: 5912.39 | D10: =VLOOKUP($B10,Sheet1!$B$2:$G$52,MATCH('Financial Data'!D$5,Sheet1!$B$2:$G$2,0),0) -> 0 | E10: =VLOOKUP($B10,Sheet1!$B$2:$G$52,MATCH('Financial Data'!E$5,Sheet1!$B$2:$G$2,0),0) -> 0 | F10: =VLOOKUP($B10,Sheet1!$B$2:$G$52,MATCH('Financial Data'!F$5,Sheet1!$B$2:$G$2,0),0) -> 0 | G10: =VLOOKUP($B10,Sheet1!$B$2:$G$52,MATCH('Financial Data'!G$5,Sheet1!$B$2:$G$2,0),0) -> 0 | H10: =VLOOKUP($B10,Sheet1!$B$2:$G$52,MATCH('Financial Data'!H$5,Sheet1!$B$2:$G$2,0),0) -> 0
A11: REV | B11: Implementation Tier 3 | C11: 62.43 | D11: =Sheet1!C9 -> 0 | E11: =Sheet1!D9 -> 0 | F11: =Sheet1!E9 -> 0 | G11: =Sheet1!F9 -> 0 | H11: =Sheet1!G9 -> 0
A12: REV | B12: Discounts | C12: 3845.54 | D12: =VLOOKUP($B12,Sheet1!$B$2:$G$52,MATCH('Financial Data'!D$5,Sheet1!$B$2:$G$2,0),0) -> 0 | E12: =VLOOKUP($B12,Sheet1!$B$2:$G$52,MATCH('Financial Data'!E$5,Sheet1!$B$2:$G$2,0),0) -> 0 | F12: =VLOOKUP($B12,Sheet1!$B$2:$G$52,MATCH('Financial Data'!F$5,Sheet1!$B$2:$G$2,0),0) -> 0 | G12: =VLOOKUP($B12,Sheet1!$B$2:$G$52,MATCH('Financial Data'!G$5,Sheet1!$B$2:$G$2,0),0) -> 0 | H12: =VLOOKUP($B12,Sheet1!$B$2:$G$52,MATCH('Financial Data'!H$5,Sheet1!$B$2:$G$2,0),0) -> 0
A13: REV | B13: Customer Discounts | C13: 2531.46 | D13: =VLOOKUP($B13,Sheet1!$B$2:$G$52,MATCH('Financial Data'!D$5,Sheet1!$B$2:$G$2,0),0) -> -565.67 | E13: =VLOOKUP($B13,Sheet1!$B$2:$G$52,MATCH('Financial Data'!E$5,Sheet1!$B$2:$G$2,0),0) -> -565.67 | F13: =VLOOKUP($B13,Sheet1!$B$2:$G$52,MATCH('Financial Data'!F$5,Sheet1!$B$2:$G$2,0),0) -> -565.67 | G13: =VLOOKUP($B13,Sheet1!$B$2:$G$52,MATCH('Financial Data'!G$5,Sheet1!$B$2:$G$2,0),0) -> -565.67 | H13: =VLOOKUP($B13,Sheet1!$B$2:$G$52,MATCH('Financial Data'!H$5,Sheet1!$B$2:$G$2,0),0) -> 0
B14: Cost of Sales | C14: 2149.91
A15: VCOS | B15: Implementation Costs | C15: 773.08 | D15: =Sheet1!C13 -> 0 | E15: =Sheet1!D13 -> 0 | F15: =Sheet1!E13 -> 0 | G15: =Sheet1!F13 -> 0 | H15: =Sheet1!G13 -> 0
A16: VCOS | B16: Implementation Payroll & Employee Expenses | D16: =Sheet1!C14 -> 0 | E16: =Sheet1!D14 -> 0 | F16: =Sheet1!E14 -> 0 | G16: =Sheet1!F14 -> 0 | H16: =Sheet1!G14 -> 0
A17: VCOS | B17: =Sheet1!B15 -> Payroll Expenses (Implementation) | C17: 200 | D17: =Sheet1!C15 -> 24418.58 | E17: =Sheet1!D15 -> 16601.56 | F17: =Sheet1!E15 -> 16491.56 | G17: =Sheet1!F15 -> 7355.78 | H17: =Sheet1!G15 -> 0
A18: VCOS | B18: =Sheet1!B16 -> Payroll Taxes (Implementation) | C18: 15 | D18: =Sheet1!C16 -> 1633.08 | E18: =Sheet1!D16 -> 1197.09 | F18: =Sheet1!E16 -> 1189.45 | G18: =Sheet1!F16 -> 594.72 | H18: =Sheet1!G16 -> 0
A19: VCOS | B19: Server Hosting Charges | C19: 99.01 | D19: =Sheet1!C17 -> 1364.26 | E19: =Sheet1!D17 -> 1530.25 | F19: =Sheet1!E17 -> 2616.47 | G19: =Sheet1!F17 -> 1600.58 | H19: =Sheet1!G17 -> 1596.51
A20: VCOS | B20: Customer Success Payroll & Employee Expenses | C20: 0 | D20: =Sheet1!C18 -> 0 | E20: =Sheet1!D18 -> 0 | F20: =Sheet1!E18 -> 0 | G20: =Sheet1!F18 -> 0 | H20: =Sheet1!G18 -> 0
A21: VCOS | B21: Payroll Expenses (Customer Success) | C21: 66.48 | D21: =Sheet1!C19 -> 2957.89 | E21: =Sheet1!D19 -> 2203.27 | F21: =Sheet1!E19 -> 2175.77 | G21: =Sheet1!F19 -> 865.39 | H21: =Sheet1!G19 -> 0
A22: VCOS | B22: Payroll Taxes (Customer Success) | C22: 164.98 | D22: =Sheet1!C20 -> 184.54 | E22: =Sheet1!D20 -> 141.48 | F22: =Sheet1!E20 -> 142.25 | G22: =Sheet1!F20 -> 71.13 | H22: =Sheet1!G20 -> 0
B23: Expenses | C23: 10880
A24: FEXP | B24: Sales and Marketing Costs | C24: 15.21 | D24: =Sheet1!C22 -> 0 | E24: =Sheet1!D22 -> 0 | F24: =Sheet1!E22 -> 0 | G24: =Sheet1!F22 -> 0 | H24: =Sheet1!G22 -> 0
A25: FEXP | B25: Operating Payroll & Employee Expenses | C25: 29.88 | D25: =Sheet1!C23 -> 0 | E25: =Sheet1!D23 -> 0 | F25: =Sheet1!E23 -> 0 | G25: =Sheet1!F23 -> 28172.03 | H25: =Sheet1!G23 -> 56579.49
A26: FEXP | B26: Payroll Expenses (Operating) | C26: 0 | D26: =Sheet1!C24 -> 5346.16 | E26: =Sheet1!D24 -> 3846.15 | F26: =Sheet1!E24 -> 5328 | G26: =Sheet1!F24 -> 1923.08 | H26: =Sheet1!G24 -> 0
A27: FEXP | B27: Payroll Taxes (Operating) | C27: 0 | D27: =Sheet1!C25 -> 360.62 | E27: =Sheet1!D25 -> 339.61 | F27: =Sheet1!E25 -> 343.46 | G27: =Sheet1!F25 -> 171.73 | H27: =Sheet1!G25 -> 0
A28: FEXP | B28: Employee Benefits & Insurance Expense | C28: 1492.31 | D28: =Sheet1!C26 -> 0 | E28: =Sheet1!D26 -> 0 | F28: =Sheet1!E26 -> 1001 | G28: =Sheet1!F26 -> 1001 | H28: =Sheet1!G26 -> 0
A29: FEXP | B29: Travel and expenses (Operating) | C29: 16555.22 | D29: =Sheet1!C27 -> 8188.52 | E29: =Sheet1!D27 -> 6222.27 | F29: =Sheet1!E27 -> 229.02 | G29: =Sheet1!F27 -> 0 | H29: =Sheet1!G27 -> 0
A30: FEXP | B30: Marketing Tech Stack (3rd party software subscriptions) | C30: 0 | D30: =Sheet1!C28 -> 508.96 | E30: =Sheet1!D28 -> 0 | F30: =Sheet1!E28 -> 0 | G30: =Sheet1!F28 -> 0 | H30: =Sheet1!G28 -> 0
A31: FEXP | B31: Events - Tradeshows and Conferences | C31: 166.4 | D31: =Sheet1!C29 -> 0 | E31: =Sheet1!D29 -> 250 | F31: =Sheet1!E29 -> 7779.88 | G31: =Sheet1!F29 -> 250 | H31: =Sheet1!G29 -> 250
A32: FEXP | B32: Travel/Meals (internal teammembers) | C32: 1956.29 | D32: =Sheet1!C30 -> 138.92 | E32: =Sheet1!D30 -> 1303.19 | F32: =Sheet1!E30 -> 1464.5 | G32: =Sheet1!F30 -> 29.59 | H32: =Sheet1!G30 -> 0
A33: FEXP | B33: Marketing Tech Stack | C33: 130 | D33: =Sheet1!C31 -> 0 | E33: =Sheet1!D31 -> 0 | F33: =Sheet1!E31 -> 0 | G33: =Sheet1!F31 -> 0 | H33: =Sheet1!G31 -> 0
A34: FEXP | B34: PR/Media | C34: 11.2 | D34: =Sheet1!C32 -> 1105.4 | E34: =Sheet1!D32 -> 1416 | F34: =Sheet1!E32 -> 1760.13 | G34: =Sheet1!F32 -> 0 | H34: =Sheet1!G32 -> 0
A35: FEXP | B35: Demand Generation | C35: 303.36 | D35: =Sheet1!C33 -> 68.06 | E35: =Sheet1!D33 -> 68.06 | F35: =Sheet1!E33 -> 783.88 | G35: =Sheet1!F33 -> 68.06 | H35: =Sheet1!G33 -> 68.06
A36: FEXP | B36: Software subscription (P&E) | C36: 767.81 | D36: =Sheet1!C34 -> 120 | E36: =Sheet1!D34 -> 120 | F36: =Sheet1!E34 -> -439.75 | G36: =Sheet1!F34 -> 164 | H36: =Sheet1!G34 -> 164
A37: FEXP | B37: Product and Engineering | D37: =Sheet1!C35 -> 0 | E37: =Sheet1!D35 -> 0 | F37: =Sheet1!E35 -> 0 | G37: =Sheet1!F35 -> 0 | H37: =Sheet1!G35 -> 0
A38: FEXP | B38: Product & Engineering Payroll & Employee Expenses | C38: 688.93 | D38: =Sheet1!C36 -> 0 | E38: =Sheet1!D36 -> 0 | F38: =Sheet1!E36 -> 0 | G38: =Sheet1!F36 -> 0 | H38: =Sheet1!G36 -> 0
A39: FEXP | B39: People cost- Product & Engineering | C39: 0 | D39: =Sheet1!C37 -> 1730.77 | E39: =Sheet1!D37 -> 1153.85 | F39: =Sheet1!E37 -> 1153.84 | G39: =Sheet1!F37 -> 5384.62 | H39: =Sheet1!G37 -> 0
A40: FEXP | B40: Payroll Taxes | D40: =Sheet1!C38 -> 159.12 | E40: =Sheet1!D38 -> 101.88 | F40: =Sheet1!E38 -> 103.04 | G40: =Sheet1!F38 -> 577.97 | H40: =Sheet1!G38 -> 0
A41: FEXP | B41: External Consultants | C41: 1744.3 | D41: =Sheet1!C39 -> 0 | E41: =Sheet1!D39 -> 0 | F41: =Sheet1!E39 -> 2467.25 | G41: =Sheet1!F39 -> 0 | H41: =Sheet1!G39 -> 0
A42: FEXP | B42: Software subscription | D42: =Sheet1!C40 -> 171.12 | E42: =Sheet1!D40 -> 171.69 | F42: =Sheet1!E40 -> 170.48 | G42: =Sheet1!F40 -> 436.27 | H42: =Sheet1!G40 -> 149.79
...

Sheet Sheet1
C2: Jan 2025 | D2: Feb 2025 | E2: Mar 2025 | F2: Apr 2025 | G2: May 2025
B4: Income
B5: Tier 3 | C5: 5813.85 | D5: 5813.85 | E5: 5873.85 | F5: 5873.85 | G5: 5248.18
B6: Other Optional Suites
B7: DCA Monitoring | E7: 0 | F7: 0 | G7: 0
B8: Implementation
B9: Tier 3
B10: Discounts | C10: 0 | D10: 0 | E10: 0 | F10: 0 | G10: 0
B11: Customer Discounts | C11: -565.67 | D11: -565.67 | E11: -565.67 | F11: -565.67 | G11: 0
B12: =#VALUE! -> #VALUE! | C12: 5248.18 | D12: 5248.18 | E12: 5308.18 | F12: 5308.18 | G12: 5248.18
B13: Implementation Costs
B14: Implementation Payroll & Employee Expenses
B15: Payroll Expenses (Implementation) | C15: 24418.58 | D15: 16601.56 | E15: 16491.56 | F15: 7355.78
B16: Payroll Taxes (Implementation) | C16: 1633.08 | D16: 1197.09 | E16: 1189.45 | F16: 594.72
B17: Server Hosting Charges | C17: 1364.26 | D17: 1530.25 | E17: 2616.47 | F17: 1600.58 | G17: 1596.51
B18: Customer Success Payroll & Employee Expenses
B19: Payroll Expenses | C19: 2957.89 | D19: 2203.27 | E19: 2175.77 | F19: 865.39
B20: Payroll Taxes | C20: 184.54 | D20: 141.48 | E20: 142.25 | F20: 71.13
B21: 500000 Cost of goods sold | C21: 30558.35 | D21: 21673.65 | E21: 22615.5 | F21: 10487.6 | G21: 1596.51
B22: Sales and Marketing Costs
B23: Operating Payroll & Employee Expenses | F23: 28172.03 | G23: 56579.49
B24: Payroll Expenses | C24: 5346.16 | D24: 3846.15 | E24: 5328 | F24: 1923.08
B25: Payroll Taxes | C25: 360.62 | D25: 339.61 | E25: 343.46 | F25: 171.73
B26: Employee Benefits & Insurance Expense | E26: 1001 | F26: 1001
B27: Travel and expenses (Operating) | C27: 8188.52 | D27: 6222.27 | E27: 229.02
B28: Marketing Tech Stack (3rd party software subscriptions) | C28: 508.96
B29: Events - Tradeshows and Conferences | D29: 250 | E29: 7779.88 | F29: 250 | G29: 250
B30: Travel/Meals (internal teammembers) | C30: 138.92 | D30: 1303.19 | E30: 1464.5 | F30: 29.59
B31: Marketing Tech Stack
B32: PR/Media | C32: 1105.4 | D32: 1416 | E32: 1760.13
B33: Demand Generation | C33: 68.06 | D33: 68.06 | E33: 783.88 | F33: 68.06 | G33: 68.06
B34: Software subscription | C34: 120 | D34: 120 | E34: -439.75 | F34: 164 | G34: 164
B35: Product and Engineering
B36: Product & Engineering Payroll & Employee Expenses
B37: People cost- Product & Engineering | C37: 1730.77 | D37: 1153.85 | E37: 1153.84 | F37: 5384.62
B38: Payroll Taxes | C38: 159.12 | D38: 101.88 | E38: 103.04 | F38: 577.97
B39: External Consultants | E39: 2467.25
B40: Software subscription | C40: 171.12 | D40: 171.69 | E40: 170.48 | F40: 436.27 | G40: 149.79
B41: Operations- People cost | C41: 4185 | D41: 2307.7 | E41: 2307.7 | F41: 1153.85
B42: Payroll Taxes | C42: 662.84 | D42: 1024.98 | E42: 1403.12 | F42: 695.23
...

Sheet KPI Sheet
A1: KPI | B1: This Month | C1: Last Month | D1: Variance | E1: Variance % | F1: YTD
A2: Core Saas Metrics
A3: MRR | B3: ='Financial Data'!H7+'Financial Data'!H10 -> 5248.18 | C3: ='Financial Data'!G7+'Financial Data'!G10 -> 5873.85 | D3: =(B3-C3) -> -625.67 | E3: -0.11 | F3: 5665
A4: ARR | B4: =B3*12 -> 62978.16 | C4: =C3*12 -> 70486.2 | D4: =(B4-C4) -> -7508.04 | E4: -0.11 | F4: =F3*12 -> 67980
A5: Sales & Growth
A6: CAC | B6: 0 | C6: 0 | D6: =(B6-C6) -> 0 | E6: =IFERROR(D6/C6,0) -> 0 | F6: 0
A7: LTV | B7: 328 | C7: 328 | D7: =(B7-C7) -> 0 | E7: =IFERROR(D7/C7,0) -> 0 | F7: 0
A8: LTV Ratio | B8: 0 | C8: 0 | D8: =(B8-C8) -> 0 | E8: =IFERROR(D8/C8,0) -> 0 | F8: 0
A9: Go-to-Market
A10: Total Customer Count | B10: =SUM(B11:B12) -> 16 | C10: =SUM(C11:C12) -> 16 | D10: =(B10-C10) -> 0 | E10: =IFERROR(D10/C10,0) -> 0 | F10: =SUM(F11:F12) -> 16
A11: Live | B11: 16 | C11: 16 | D11: =(B11-C11) -> 0 | E11: =IFERROR(D11/C11,0) -> 0 | F11: 16
A12: Implementation | B12: 0 | C12: 0 | D12: =(B12-C12) -> 0 | E12: =IFERROR(D12/C12,0) -> 0 | F12: 0
A13: Capital Efficiency
A14: Cash RunWay | B14: 6 | C14: 3 | D14: =(B14-C14) -> 3 | E14: 1 | F14: 1
A15: Burn Rate | B15: 358522 | C15: 291420 | D15: =(B15-C15) -> 67102 | E15: 0.23 | F15: 358522
A16: Profitability
A17: Gross Margin | B17: -0.15 | C17: -3.93 | D17: =B17-C17 -> 3.78 | E17: -0.96 | F17: 4.1075
A18: Operating Margin | B18: -4.25 | C18: -16.34 | D18: =B18-C18 -> 12.09 | E18: -0.74 | F18: 15.0746
